{"name": "test_login[standard_user-2452]", "status": "failed", "statusDetails": {"message": "AssertionError: Invalid credentials\nassert 'Epic sadface... this service' == ''\n  \n  + Epic sadface: Username and password do not match any user in this service", "trace": "username = 'standard_user', password = '2452'\n\n    @pytest.mark.login\n    @pytest.mark.usefixtures('log_on_failure')\n    @pytest.mark.parametrize(\"username, password\", get_data())\n    def test_login(username, password):\n        global driver, page\n        msg = page.Login(username, password)\n        allure.attach(driver.get_screenshot_as_png(), name=\"Login\", attachment_type=AttachmentType.PNG)\n>       assert msg == '', 'Invalid credentials'\nE       AssertionError: Invalid credentials\nE       assert 'Epic sadface... this service' == ''\nE         \nE         + Epic sadface: Username and password do not match any user in this service\n\nreports\\test_04_pytest_allure_screenshot_error.py:44: AssertionError"}, "attachments": [{"name": "Login", "source": "bc649739-a942-4e9f-83b6-34a40b863515-attachment.png", "type": "image/png"}, {"name": "stdout", "source": "f18c44c7-6521-4fc0-a7bd-1ac00c625d00-attachment.txt", "type": "text/plain"}], "parameters": [{"name": "username", "value": "'standard_user'"}, {"name": "password", "value": "'2452'"}], "start": 1707773465920, "stop": 1707773466790, "uuid": "03b4d308-fe7d-4f3a-860d-64d2a23c03cb", "historyId": "65bb44aca08e3c12704bbfb894cc0eda", "testCaseId": "d3da2953cdfd9c49173b93a1b4e4916c", "fullName": "reports.test_04_pytest_allure_screenshot_error#test_login", "labels": [{"name": "tag", "value": "@pytest.mark.usefixtures('log_on_failure')"}, {"name": "tag", "value": "login"}, {"name": "parentSuite", "value": "reports"}, {"name": "suite", "value": "test_04_pytest_allure_screenshot_error"}, {"name": "host", "value": "DESKTOP-551JSCE"}, {"name": "thread", "value": "72136-MainThread"}, {"name": "framework", "value": "pytest"}, {"name": "language", "value": "cpython3"}, {"name": "package", "value": "reports.test_04_pytest_allure_screenshot_error"}]}